---
title:  "(WIL) 에러 처리 중 finally를 써야만 하는가?"
excerpt: "헷갈렸던 부분과 잘 몰랐던 개념을 조금씩 알게 된다. 기초부터 빈틈을 채우기로 했던 목적을 꼭 기억하자."

categories:
  - TIL
tags:
  - [TIL, 내일배움캠프, 스파르타내일배움캠프, AI, 파이썬, 라이브러리, 판다스, 데이터프레임]

toc: true

last_modified_at: 2024-11-29
thumbnail: ../assets/TIL.jpg
---

# finally 정리
- finally: 예외 발생 여부와 관계없이 항상 실행되는 코드 블록

## 사용 목적:
- 리소스 정리: 파일 닫기, 네트워크 연결 해제, 데이터베이스 연결 종료 등을 보장
- 종료 작업 보장: 예외와 관계없이 반드시 실행해야 하는 작업을 수행

## 특징
try 블록에서 예외가 발생해도, 발생하지 않아도 실행된다. 사실 이는 try 문 바깥에 평상시처럼 코드를 작성해도 실행이 되기에 나는 왜 finally를 구태여 적어주는지 이해가 가지 않았다. 그러던 중 finally만이 가지는 특징을 발견했다.
[Finally가 필요한 이유 - 코드잇](https://www.codeit.kr/community/questions/UXVlc3Rpb246NjA5YmUzN2E0NzUyNWU2NjliNmMxODIw)

(자바스크립트 Q&A이긴 하지만 일맥상통하는 내용이라 도움을 받음)
그렇다. finally는 try나 except 블록에서 `return`이 호출되더라도 실행된다. 따라서 한 동작을 마친 뒤, 마지막에 통일성 있게 특정 구문을 실행하고 싶을 때 finally를 사용하면 좋을 것 같다.

아래는 다른 조에서 try 구문을 발표하면서 만들어주신 깔끔한 예시이다. 
```py
# 사용자 데이터 (예시)
user_data = {
    "username": "testuser",
    "password": "securepassword123"
}
def validate_username(input_username):
    """아이디 확인"""
    try:
        if input_username != user_data["username"]:
            raise KeyError("사용자 정보가 없습니다.")  # 아이디 틀림
        else :
            print("아이디가 확인되었습니다.")
            return True
    except KeyError as ke:
        print(f"오류: {ke}")
        return False
def validate_password(input_password):
    """비밀번호 확인"""
    try:
        if input_password != user_data["password"]:
            raise ValueError("비밀번호가 틀렸습니다.")  # 비밀번호 틀림
        else :
            print("비밀번호가 확인되었습니다.")
            return True
    except ValueError as ve:
        print(f"오류: {ve}")
        return False
def login_system():
    """로그인 프로세스"""
    try:
        # 아이디 입력 및 검증
        username = input("아이디를 입력하세요: ")
        if not validate_username(username):
            return  # 아이디 틀리면 종료
        # 비밀번호 입력 및 검증
        password = input("비밀번호를 입력하세요: ")
        if not validate_password(password):
            return  # 비밀번호 틀리면 종료
        # 로그인 성공
        print("로그인 성공! 환영합니다.")
    except Exception as e:
        # 기타 예외 처리
        print(f"알 수 없는 오류가 발생했습니다: {e}")
    finally:
        # 항상 실행되는 메시지
        print("로그인 시도를 종료합니다.")
# 로그인 실행
login_system()
```

# 이번주 회고
너무 쌩기초부터 공부하는 것이라 여기에 이렇게 긴 시간을 할애할 필요가 있나 싶었는데, 그러면서도 헷갈렸던 부분과 잘 몰랐던 개념을 조금씩 알게 된다. 기초부터 빈틈을 채우기로 했던 목적을 꼭 기억하자.